Module message: Setting OPENBLAS_NUM_THREADS to 1. Done. 
rm: cannot remove ‘data/Samples/*’: No such file or directory
rm: cannot remove ‘data/Tidy_Topics/*’: No such file or directory
rm: cannot remove ‘data/Tree_Distance/*’: No such file or directory
Traceback (most recent call last):
  File "/hpcfs/users/a1670295/Topic_distance_different_corpora/Python/phoenix_hSBM.py", line 16, in <module>
    sub_info = pd.read_csv("data/Subs.info/sub_info.csv")
  File "/hpcfs/users/a1670295/myconda/envs/gt/lib/python3.9/site-packages/pandas/io/parsers.py", line 610, in read_csv
Traceback (most recent call last):
  File "/hpcfs/users/a1670295/Topic_distance_different_corpora/Python/phoenix_hSBM.py", line 16, in <module>
Traceback (most recent call last):
  File "/hpcfs/users/a1670295/Topic_distance_different_corpora/Python/phoenix_hSBM.py", line 16, in <module>
    sub_info = pd.read_csv("data/Subs.info/sub_info.csv")
  File "/hpcfs/users/a1670295/myconda/envs/gt/lib/python3.9/site-packages/pandas/io/parsers.py", line 610, in read_csv
Traceback (most recent call last):
  File "/hpcfs/users/a1670295/Topic_distance_different_corpora/Python/phoenix_hSBM.py", line 16, in <module>
    sub_info = pd.read_csv("data/Subs.info/sub_info.csv")
  File "/hpcfs/users/a1670295/myconda/envs/gt/lib/python3.9/site-packages/pandas/io/parsers.py", line 610, in read_csv
Traceback (most recent call last):
  File "/hpcfs/users/a1670295/Topic_distance_different_corpora/Python/phoenix_hSBM.py", line 16, in <module>
    sub_info = pd.read_csv("data/Subs.info/sub_info.csv")
  File "/hpcfs/users/a1670295/myconda/envs/gt/lib/python3.9/site-packages/pandas/io/parsers.py", line 610, in read_csv
    sub_info = pd.read_csv("data/Subs.info/sub_info.csv")
  File "/hpcfs/users/a1670295/myconda/envs/gt/lib/python3.9/site-packages/pandas/io/parsers.py", line 610, in read_csv
    return _read(filepath_or_buffer, kwds)
    return _read(filepath_or_buffer, kwds)
  File "/hpcfs/users/a1670295/myconda/envs/gt/lib/python3.9/site-packages/pandas/io/parsers.py", line 462, in _read
  File "/hpcfs/users/a1670295/myconda/envs/gt/lib/python3.9/site-packages/pandas/io/parsers.py", line 462, in _read
    parser = TextFileReader(filepath_or_buffer, **kwds)
  File "/hpcfs/users/a1670295/myconda/envs/gt/lib/python3.9/site-packages/pandas/io/parsers.py", line 819, in __init__
    parser = TextFileReader(filepath_or_buffer, **kwds)
  File "/hpcfs/users/a1670295/myconda/envs/gt/lib/python3.9/site-packages/pandas/io/parsers.py", line 819, in __init__
    self._engine = self._make_engine(self.engine)
  File "/hpcfs/users/a1670295/myconda/envs/gt/lib/python3.9/site-packages/pandas/io/parsers.py", line 1050, in _make_engine
    self._engine = self._make_engine(self.engine)
  File "/hpcfs/users/a1670295/myconda/envs/gt/lib/python3.9/site-packages/pandas/io/parsers.py", line 1050, in _make_engine
    return mapping[engine](self.f, **self.options)  # type: ignore[call-arg]
  File "/hpcfs/users/a1670295/myconda/envs/gt/lib/python3.9/site-packages/pandas/io/parsers.py", line 1867, in __init__
    return mapping[engine](self.f, **self.options)  # type: ignore[call-arg]
  File "/hpcfs/users/a1670295/myconda/envs/gt/lib/python3.9/site-packages/pandas/io/parsers.py", line 1867, in __init__
    self._open_handles(src, kwds)
  File "/hpcfs/users/a1670295/myconda/envs/gt/lib/python3.9/site-packages/pandas/io/parsers.py", line 1362, in _open_handles
    self._open_handles(src, kwds)
  File "/hpcfs/users/a1670295/myconda/envs/gt/lib/python3.9/site-packages/pandas/io/parsers.py", line 1362, in _open_handles
    return _read(filepath_or_buffer, kwds)
  File "/hpcfs/users/a1670295/myconda/envs/gt/lib/python3.9/site-packages/pandas/io/parsers.py", line 462, in _read
    parser = TextFileReader(filepath_or_buffer, **kwds)
  File "/hpcfs/users/a1670295/myconda/envs/gt/lib/python3.9/site-packages/pandas/io/parsers.py", line 819, in __init__
    self.handles = get_handle(
  File "/hpcfs/users/a1670295/myconda/envs/gt/lib/python3.9/site-packages/pandas/io/common.py", line 642, in get_handle
    self._engine = self._make_engine(self.engine)
  File "/hpcfs/users/a1670295/myconda/envs/gt/lib/python3.9/site-packages/pandas/io/parsers.py", line 1050, in _make_engine
    return _read(filepath_or_buffer, kwds)
  File "/hpcfs/users/a1670295/myconda/envs/gt/lib/python3.9/site-packages/pandas/io/parsers.py", line 462, in _read
    parser = TextFileReader(filepath_or_buffer, **kwds)
  File "/hpcfs/users/a1670295/myconda/envs/gt/lib/python3.9/site-packages/pandas/io/parsers.py", line 819, in __init__
    return mapping[engine](self.f, **self.options)  # type: ignore[call-arg]
  File "/hpcfs/users/a1670295/myconda/envs/gt/lib/python3.9/site-packages/pandas/io/parsers.py", line 1867, in __init__
    self._engine = self._make_engine(self.engine)
  File "/hpcfs/users/a1670295/myconda/envs/gt/lib/python3.9/site-packages/pandas/io/parsers.py", line 1050, in _make_engine
    return mapping[engine](self.f, **self.options)  # type: ignore[call-arg]
  File "/hpcfs/users/a1670295/myconda/envs/gt/lib/python3.9/site-packages/pandas/io/parsers.py", line 1867, in __init__
    self._open_handles(src, kwds)
  File "/hpcfs/users/a1670295/myconda/envs/gt/lib/python3.9/site-packages/pandas/io/parsers.py", line 1362, in _open_handles
    self._open_handles(src, kwds)
  File "/hpcfs/users/a1670295/myconda/envs/gt/lib/python3.9/site-packages/pandas/io/parsers.py", line 1362, in _open_handles
    self.handles = get_handle(
  File "/hpcfs/users/a1670295/myconda/envs/gt/lib/python3.9/site-packages/pandas/io/common.py", line 642, in get_handle
    self.handles = get_handle(
  File "/hpcfs/users/a1670295/myconda/envs/gt/lib/python3.9/site-packages/pandas/io/common.py", line 642, in get_handle
    self.handles = get_handle(
  File "/hpcfs/users/a1670295/myconda/envs/gt/lib/python3.9/site-packages/pandas/io/common.py", line 642, in get_handle
    return _read(filepath_or_buffer, kwds)
  File "/hpcfs/users/a1670295/myconda/envs/gt/lib/python3.9/site-packages/pandas/io/parsers.py", line 462, in _read
    parser = TextFileReader(filepath_or_buffer, **kwds)
  File "/hpcfs/users/a1670295/myconda/envs/gt/lib/python3.9/site-packages/pandas/io/parsers.py", line 819, in __init__
    self._engine = self._make_engine(self.engine)
  File "/hpcfs/users/a1670295/myconda/envs/gt/lib/python3.9/site-packages/pandas/io/parsers.py", line 1050, in _make_engine
    return mapping[engine](self.f, **self.options)  # type: ignore[call-arg]
  File "/hpcfs/users/a1670295/myconda/envs/gt/lib/python3.9/site-packages/pandas/io/parsers.py", line 1867, in __init__
    self._open_handles(src, kwds)
  File "/hpcfs/users/a1670295/myconda/envs/gt/lib/python3.9/site-packages/pandas/io/parsers.py", line 1362, in _open_handles
    self.handles = get_handle(
  File "/hpcfs/users/a1670295/myconda/envs/gt/lib/python3.9/site-packages/pandas/io/common.py", line 642, in get_handle
    handle = open(
    handle = open(
FileNotFoundError: [Errno 2] No such file or directory: 'data/Subs.info/sub_info.csv'
FileNotFoundError: [Errno 2] No such file or directory: 'data/Subs.info/sub_info.csv'
    handle = open(
    handle = open(
FileNotFoundError: [Errno 2] No such file or directory: 'data/Subs.info/sub_info.csv'
FileNotFoundError: [Errno 2] No such file or directory: 'data/Subs.info/sub_info.csv'
    handle = open(
FileNotFoundError: [Errno 2] No such file or directory: 'data/Subs.info/sub_info.csv'
Traceback (most recent call last):
  File "/hpcfs/users/a1670295/Topic_distance_different_corpora/Python/phoenix_hSBM.py", line 16, in <module>
    sub_info = pd.read_csv("data/Subs.info/sub_info.csv")
  File "/hpcfs/users/a1670295/myconda/envs/gt/lib/python3.9/site-packages/pandas/io/parsers.py", line 610, in read_csv
    return _read(filepath_or_buffer, kwds)
  File "/hpcfs/users/a1670295/myconda/envs/gt/lib/python3.9/site-packages/pandas/io/parsers.py", line 462, in _read
    parser = TextFileReader(filepath_or_buffer, **kwds)
  File "/hpcfs/users/a1670295/myconda/envs/gt/lib/python3.9/site-packages/pandas/io/parsers.py", line 819, in __init__
    self._engine = self._make_engine(self.engine)
  File "/hpcfs/users/a1670295/myconda/envs/gt/lib/python3.9/site-packages/pandas/io/parsers.py", line 1050, in _make_engine
    return mapping[engine](self.f, **self.options)  # type: ignore[call-arg]
  File "/hpcfs/users/a1670295/myconda/envs/gt/lib/python3.9/site-packages/pandas/io/parsers.py", line 1867, in __init__
    self._open_handles(src, kwds)
  File "/hpcfs/users/a1670295/myconda/envs/gt/lib/python3.9/site-packages/pandas/io/parsers.py", line 1362, in _open_handles
    self.handles = get_handle(
  File "/hpcfs/users/a1670295/myconda/envs/gt/lib/python3.9/site-packages/pandas/io/common.py", line 642, in get_handle
    handle = open(
FileNotFoundError: [Errno 2] No such file or directory: 'data/Subs.info/sub_info.csv'
Traceback (most recent call last):
  File "/hpcfs/users/a1670295/Topic_distance_different_corpora/Python/phoenix_hSBM.py", line 16, in <module>
    sub_info = pd.read_csv("data/Subs.info/sub_info.csv")
  File "/hpcfs/users/a1670295/myconda/envs/gt/lib/python3.9/site-packages/pandas/io/parsers.py", line 610, in read_csv
    return _read(filepath_or_buffer, kwds)
  File "/hpcfs/users/a1670295/myconda/envs/gt/lib/python3.9/site-packages/pandas/io/parsers.py", line 462, in _read
    parser = TextFileReader(filepath_or_buffer, **kwds)
  File "/hpcfs/users/a1670295/myconda/envs/gt/lib/python3.9/site-packages/pandas/io/parsers.py", line 819, in __init__
    self._engine = self._make_engine(self.engine)
  File "/hpcfs/users/a1670295/myconda/envs/gt/lib/python3.9/site-packages/pandas/io/parsers.py", line 1050, in _make_engine
    return mapping[engine](self.f, **self.options)  # type: ignore[call-arg]
  File "/hpcfs/users/a1670295/myconda/envs/gt/lib/python3.9/site-packages/pandas/io/parsers.py", line 1867, in __init__
    self._open_handles(src, kwds)
  File "/hpcfs/users/a1670295/myconda/envs/gt/lib/python3.9/site-packages/pandas/io/parsers.py", line 1362, in _open_handles
    self.handles = get_handle(
  File "/hpcfs/users/a1670295/myconda/envs/gt/lib/python3.9/site-packages/pandas/io/common.py", line 642, in get_handle
    handle = open(
FileNotFoundError: [Errno 2] No such file or directory: 'data/Subs.info/sub_info.csv'
Traceback (most recent call last):
  File "/hpcfs/users/a1670295/Topic_distance_different_corpora/Python/phoenix_hSBM.py", line 16, in <module>
    sub_info = pd.read_csv("data/Subs.info/sub_info.csv")
  File "/hpcfs/users/a1670295/myconda/envs/gt/lib/python3.9/site-packages/pandas/io/parsers.py", line 610, in read_csv
    return _read(filepath_or_buffer, kwds)
  File "/hpcfs/users/a1670295/myconda/envs/gt/lib/python3.9/site-packages/pandas/io/parsers.py", line 462, in _read
    parser = TextFileReader(filepath_or_buffer, **kwds)
  File "/hpcfs/users/a1670295/myconda/envs/gt/lib/python3.9/site-packages/pandas/io/parsers.py", line 819, in __init__
    self._engine = self._make_engine(self.engine)
  File "/hpcfs/users/a1670295/myconda/envs/gt/lib/python3.9/site-packages/pandas/io/parsers.py", line 1050, in _make_engine
    return mapping[engine](self.f, **self.options)  # type: ignore[call-arg]
  File "/hpcfs/users/a1670295/myconda/envs/gt/lib/python3.9/site-packages/pandas/io/parsers.py", line 1867, in __init__
    self._open_handles(src, kwds)
  File "/hpcfs/users/a1670295/myconda/envs/gt/lib/python3.9/site-packages/pandas/io/parsers.py", line 1362, in _open_handles
    self.handles = get_handle(
  File "/hpcfs/users/a1670295/myconda/envs/gt/lib/python3.9/site-packages/pandas/io/common.py", line 642, in get_handle
    handle = open(
FileNotFoundError: [Errno 2] No such file or directory: 'data/Subs.info/sub_info.csv'
Traceback (most recent call last):
  File "/hpcfs/users/a1670295/Topic_distance_different_corpora/Python/phoenix_hSBM.py", line 16, in <module>
    sub_info = pd.read_csv("data/Subs.info/sub_info.csv")
  File "/hpcfs/users/a1670295/myconda/envs/gt/lib/python3.9/site-packages/pandas/io/parsers.py", line 610, in read_csv
    return _read(filepath_or_buffer, kwds)
  File "/hpcfs/users/a1670295/myconda/envs/gt/lib/python3.9/site-packages/pandas/io/parsers.py", line 462, in _read
    parser = TextFileReader(filepath_or_buffer, **kwds)
  File "/hpcfs/users/a1670295/myconda/envs/gt/lib/python3.9/site-packages/pandas/io/parsers.py", line 819, in __init__
    self._engine = self._make_engine(self.engine)
  File "/hpcfs/users/a1670295/myconda/envs/gt/lib/python3.9/site-packages/pandas/io/parsers.py", line 1050, in _make_engine
    return mapping[engine](self.f, **self.options)  # type: ignore[call-arg]
  File "/hpcfs/users/a1670295/myconda/envs/gt/lib/python3.9/site-packages/pandas/io/parsers.py", line 1867, in __init__
    self._open_handles(src, kwds)
  File "/hpcfs/users/a1670295/myconda/envs/gt/lib/python3.9/site-packages/pandas/io/parsers.py", line 1362, in _open_handles
    self.handles = get_handle(
  File "/hpcfs/users/a1670295/myconda/envs/gt/lib/python3.9/site-packages/pandas/io/common.py", line 642, in get_handle
    handle = open(
FileNotFoundError: [Errno 2] No such file or directory: 'data/Subs.info/sub_info.csv'
Traceback (most recent call last):
  File "/hpcfs/users/a1670295/Topic_distance_different_corpora/Python/phoenix_hSBM.py", line 16, in <module>
    sub_info = pd.read_csv("data/Subs.info/sub_info.csv")
  File "/hpcfs/users/a1670295/myconda/envs/gt/lib/python3.9/site-packages/pandas/io/parsers.py", line 610, in read_csv
    return _read(filepath_or_buffer, kwds)
  File "/hpcfs/users/a1670295/myconda/envs/gt/lib/python3.9/site-packages/pandas/io/parsers.py", line 462, in _read
    parser = TextFileReader(filepath_or_buffer, **kwds)
  File "/hpcfs/users/a1670295/myconda/envs/gt/lib/python3.9/site-packages/pandas/io/parsers.py", line 819, in __init__
    self._engine = self._make_engine(self.engine)
  File "/hpcfs/users/a1670295/myconda/envs/gt/lib/python3.9/site-packages/pandas/io/parsers.py", line 1050, in _make_engine
    return mapping[engine](self.f, **self.options)  # type: ignore[call-arg]
  File "/hpcfs/users/a1670295/myconda/envs/gt/lib/python3.9/site-packages/pandas/io/parsers.py", line 1867, in __init__
    self._open_handles(src, kwds)
  File "/hpcfs/users/a1670295/myconda/envs/gt/lib/python3.9/site-packages/pandas/io/parsers.py", line 1362, in _open_handles
    self.handles = get_handle(
  File "/hpcfs/users/a1670295/myconda/envs/gt/lib/python3.9/site-packages/pandas/io/common.py", line 642, in get_handle
    handle = open(
FileNotFoundError: [Errno 2] No such file or directory: 'data/Subs.info/sub_info.csv'
seq: invalid floating point argument: remainder
Try 'seq --help' for more information.
python3.9: can't open file '/hpcfs/users/a1670295/Topic_distance_different_corpora/Python/phoenix_tree_dist.py': [Errno 2] No such file or directory
python3.9: can't open file '/hpcfs/users/a1670295/Topic_distance_different_corpora/Python/phoenix_tree_dist.py': [Errno 2] No such file or directory
python3.9: can't open file '/hpcfs/users/a1670295/Topic_distance_different_corpora/Python/phoenix_tree_dist.py': [Errno 2] No such file or directory
python3.9: can't open file '/hpcfs/users/a1670295/Topic_distance_different_corpora/Python/phoenix_tree_dist.py': [Errno 2] No such file or directory
python3.9: can't open file '/hpcfs/users/a1670295/Topic_distance_different_corpora/Python/phoenix_tree_dist.py': [Errno 2] No such file or directory
python3.9: can't open file '/hpcfs/users/a1670295/Topic_distance_different_corpora/Python/phoenix_tree_dist.py': [Errno 2] No such file or directory
python3.9: can't open file '/hpcfs/users/a1670295/Topic_distance_different_corpora/Python/phoenix_tree_dist.py': [Errno 2] No such file or directory
python3.9: can't open file '/hpcfs/users/a1670295/Topic_distance_different_corpora/Python/phoenix_tree_dist.py': [Errno 2] No such file or directory
python3.9: can't open file '/hpcfs/users/a1670295/Topic_distance_different_corpora/Python/phoenix_tree_dist.py': [Errno 2] No such file or directory
python3.9: can't open file '/hpcfs/users/a1670295/Topic_distance_different_corpora/Python/phoenix_tree_dist.py': [Errno 2] No such file or directory
python3.9: can't open file '/hpcfs/users/a1670295/Topic_distance_different_corpora/Python/phoenix_tree_dist.py': [Errno 2] No such file or directory
python3.9: can't open file '/hpcfs/users/a1670295/Topic_distance_different_corpora/Python/phoenix_tree_dist.py': [Errno 2] No such file or directory
python3.9: can't open file '/hpcfs/users/a1670295/Topic_distance_different_corpora/Python/phoenix_tree_dist.py': [Errno 2] No such file or directory
python3.9: can't open file '/hpcfs/users/a1670295/Topic_distance_different_corpora/Python/phoenix_tree_dist.py': [Errno 2] No such file or directory
python3.9: can't open file '/hpcfs/users/a1670295/Topic_distance_different_corpora/Python/phoenix_tree_dist.py': [Errno 2] No such file or directory
python3.9: can't open file '/hpcfs/users/a1670295/Topic_distance_different_corpora/Python/phoenix_tree_dist.py': [Errno 2] No such file or directory
python3.9: can't open file '/hpcfs/users/a1670295/Topic_distance_different_corpora/Python/phoenix_tree_dist.py': [Errno 2] No such file or directory
python3.9: can't open file '/hpcfs/users/a1670295/Topic_distance_different_corpora/Python/phoenix_tree_dist.py': [Errno 2] No such file or directory
python3.9: can't open file '/hpcfs/users/a1670295/Topic_distance_different_corpora/Python/phoenix_tree_dist.py': [Errno 2] No such file or directory
python3.9: can't open file '/hpcfs/users/a1670295/Topic_distance_different_corpora/Python/phoenix_tree_dist.py': [Errno 2] No such file or directory
python3.9: can't open file '/hpcfs/users/a1670295/Topic_distance_different_corpora/Python/phoenix_tree_dist.py': [Errno 2] No such file or directory
python3.9: can't open file '/hpcfs/users/a1670295/Topic_distance_different_corpora/Python/phoenix_tree_dist.py': [Errno 2] No such file or directory
python3.9: can't open file '/hpcfs/users/a1670295/Topic_distance_different_corpora/Python/phoenix_tree_dist.py': [Errno 2] No such file or directory
python3.9: can't open file '/hpcfs/users/a1670295/Topic_distance_different_corpora/Python/phoenix_tree_dist.py': [Errno 2] No such file or directory
python3.9: can't open file '/hpcfs/users/a1670295/Topic_distance_different_corpora/Python/phoenix_tree_dist.py': [Errno 2] No such file or directory
python3.9: can't open file '/hpcfs/users/a1670295/Topic_distance_different_corpora/Python/phoenix_tree_dist.py': [Errno 2] No such file or directory
python3.9: can't open file '/hpcfs/users/a1670295/Topic_distance_different_corpora/Python/phoenix_tree_dist.py': [Errno 2] No such file or directory
python3.9: can't open file '/hpcfs/users/a1670295/Topic_distance_different_corpora/Python/phoenix_tree_dist.py': [Errno 2] No such file or directory
python3.9: can't open file '/hpcfs/users/a1670295/Topic_distance_different_corpora/Python/phoenix_tree_dist.py': [Errno 2] No such file or directory
python3.9: can't open file '/hpcfs/users/a1670295/Topic_distance_different_corpora/Python/phoenix_tree_dist.py': [Errno 2] No such file or directory
python3.9: can't open file '/hpcfs/users/a1670295/Topic_distance_different_corpora/Python/phoenix_tree_dist.py': [Errno 2] No such file or directory
python3.9: can't open file '/hpcfs/users/a1670295/Topic_distance_different_corpora/Python/phoenix_tree_dist.py': [Errno 2] No such file or directory
python3.9: can't open file '/hpcfs/users/a1670295/Topic_distance_different_corpora/Python/phoenix_tree_dist.py': [Errno 2] No such file or directory
python3.9: can't open file '/hpcfs/users/a1670295/Topic_distance_different_corpora/Python/phoenix_tree_dist.py': [Errno 2] No such file or directory
python3.9: can't open file '/hpcfs/users/a1670295/Topic_distance_different_corpora/Python/phoenix_tree_dist.py': [Errno 2] No such file or directory
python3.9: can't open file '/hpcfs/users/a1670295/Topic_distance_different_corpora/Python/phoenix_tree_dist.py': [Errno 2] No such file or directory
python3.9: can't open file '/hpcfs/users/a1670295/Topic_distance_different_corpora/Python/phoenix_tree_dist.py': [Errno 2] No such file or directory
python3.9: can't open file '/hpcfs/users/a1670295/Topic_distance_different_corpora/Python/phoenix_tree_dist.py': [Errno 2] No such file or directory
python3.9: can't open file '/hpcfs/users/a1670295/Topic_distance_different_corpora/Python/phoenix_tree_dist.py': [Errno 2] No such file or directory
python3.9: can't open file '/hpcfs/users/a1670295/Topic_distance_different_corpora/Python/phoenix_tree_dist.py': [Errno 2] No such file or directory
python3.9: can't open file '/hpcfs/users/a1670295/Topic_distance_different_corpora/Python/phoenix_tree_dist.py': [Errno 2] No such file or directory
python3.9: can't open file '/hpcfs/users/a1670295/Topic_distance_different_corpora/Python/phoenix_tree_dist.py': [Errno 2] No such file or directory
python3.9: can't open file '/hpcfs/users/a1670295/Topic_distance_different_corpora/Python/phoenix_tree_dist.py': [Errno 2] No such file or directory
python3.9: can't open file '/hpcfs/users/a1670295/Topic_distance_different_corpora/Python/phoenix_tree_dist.py': [Errno 2] No such file or directory
python3.9: can't open file '/hpcfs/users/a1670295/Topic_distance_different_corpora/Python/phoenix_tree_dist.py': [Errno 2] No such file or directory
python3.9: can't open file '/hpcfs/users/a1670295/Topic_distance_different_corpora/Python/phoenix_tree_dist.py': [Errno 2] No such file or directory
python3.9: can't open file '/hpcfs/users/a1670295/Topic_distance_different_corpora/Python/phoenix_tree_dist.py': [Errno 2] No such file or directory
python3.9: can't open file '/hpcfs/users/a1670295/Topic_distance_different_corpora/Python/phoenix_tree_dist.py': [Errno 2] No such file or directory
python3.9: can't open file '/hpcfs/users/a1670295/Topic_distance_different_corpora/Python/phoenix_tree_dist.py': [Errno 2] No such file or directory
python3.9: can't open file '/hpcfs/users/a1670295/Topic_distance_different_corpora/Python/phoenix_tree_dist.py': [Errno 2] No such file or directory
python3.9: can't open file '/hpcfs/users/a1670295/Topic_distance_different_corpora/Python/phoenix_tree_dist.py': [Errno 2] No such file or directory
python3.9: can't open file '/hpcfs/users/a1670295/Topic_distance_different_corpora/Python/phoenix_tree_dist.py': [Errno 2] No such file or directory
python3.9: can't open file '/hpcfs/users/a1670295/Topic_distance_different_corpora/Python/phoenix_tree_dist.py': [Errno 2] No such file or directory
python3.9: can't open file '/hpcfs/users/a1670295/Topic_distance_different_corpora/Python/phoenix_tree_dist.py': [Errno 2] No such file or directory
python3.9: can't open file '/hpcfs/users/a1670295/Topic_distance_different_corpora/Python/phoenix_tree_dist.py': [Errno 2] No such file or directory
python3.9: can't open file '/hpcfs/users/a1670295/Topic_distance_different_corpora/Python/phoenix_tree_dist.py': [Errno 2] No such file or directory
python3.9: can't open file '/hpcfs/users/a1670295/Topic_distance_different_corpora/Python/phoenix_tree_dist.py': [Errno 2] No such file or directory
python3.9: can't open file '/hpcfs/users/a1670295/Topic_distance_different_corpora/Python/phoenix_tree_dist.py': [Errno 2] No such file or directory
python3.9: can't open file '/hpcfs/users/a1670295/Topic_distance_different_corpora/Python/phoenix_tree_dist.py': [Errno 2] No such file or directory
python3.9: can't open file '/hpcfs/users/a1670295/Topic_distance_different_corpora/Python/phoenix_tree_dist.py': [Errno 2] No such file or directory
python3.9: can't open file '/hpcfs/users/a1670295/Topic_distance_different_corpora/Python/phoenix_tree_dist.py': [Errno 2] No such file or directory
python3.9: can't open file '/hpcfs/users/a1670295/Topic_distance_different_corpora/Python/phoenix_tree_dist.py': [Errno 2] No such file or directory
python3.9: can't open file '/hpcfs/users/a1670295/Topic_distance_different_corpora/Python/phoenix_tree_dist.py': [Errno 2] No such file or directory
python3.9: can't open file '/hpcfs/users/a1670295/Topic_distance_different_corpora/Python/phoenix_tree_dist.py': [Errno 2] No such file or directory
python3.9: can't open file '/hpcfs/users/a1670295/Topic_distance_different_corpora/Python/phoenix_tree_dist.py': [Errno 2] No such file or directory
python3.9: can't open file '/hpcfs/users/a1670295/Topic_distance_different_corpora/Python/phoenix_tree_dist.py': [Errno 2] No such file or directory
